<?xml version="1.0"?>
<robot name="um" xmlns:xacro="http://ros.org/wiki/xacro">

    <!-- Define the colors used in the um -->
    <material name="Grey">
        <color rgba="0.75 0.75 0.75 1" />
    </material>

    <material name="Orange">
        <color rgba="1 0.4 0 1"/>
    </material>

    <material name="Black">
        <color rgba="0 0 0 1"/>
    </material>

    <material name="White">
        <color rgba="1 1 1 1"/>
    </material>

    <material name="Blue">
        <color rgba="0 0 1 1"/>
    </material>

    <material name="Red">
        <color rgba="1 0 0 1"/>
    </material>

    <material name="Green">
        <color rgba="0 1 0 1"/>
    </material>

    <!-- Define the macros used in um -->
    <xacro:macro name="inertia_matrix" params="mass">
        <inertial>
            <mass value="${mass}" />
            <inertia ixx="0.001" ixy="0"    ixz="0" 
                                     iyy="0.001" iyz="0" 
                                                 izz="0.001" />
        </inertial>
    </xacro:macro>

    <!-- Define the constants used in the um -->
    <xacro:property name="M_PI" value="3.1415926" />
    <xacro:property name="DAMPING" value="50" />
    <xacro:property name="FRICTION" value="1" />

    <!-- Joint1 properties -->
    <xacro:property name="JOINT1_COOR" value="0 0 0.5" />
    <xacro:property name="JOINT1_EFFORT" value="300" />
    <xacro:property name="JOINT1_LOWER" value="0" />
    <xacro:property name="JOINT1_UPPER" value="0.59" />
    <xacro:property name="JOINT1_VEL" value="1.0" />

    <!-- Joint2 properties -->
    <xacro:property name="JOINT2_COOR" value="0.055 -0.0075 0.1764" />
    <xacro:property name="JOINT2_EFFORT" value="300" />
    <xacro:property name="JOINT2_LOWER" value="-${M_PI}" />
    <xacro:property name="JOINT2_UPPER" value="${M_PI}" />
    <xacro:property name="JOINT2_VEL" value="1.0" />

    <!-- Joint 3 properties -->
    <xacro:property name="JOINT3_COOR" value="0.0349 0 0.0225" />
    <xacro:property name="JOINT3_EFFORT" value="300" />
    <xacro:property name="JOINT3_LOWER" value="-${M_PI}" />
    <xacro:property name="JOINT3_UPPER" value="${M_PI}" />
    <xacro:property name="JOINT3_VEL" value="1.0" />

    <!-- Joint 4 properties -->
    <xacro:property name="JOINT4_COOR" value="0.2655 0 -0.00025" />
    <xacro:property name="JOINT4_EFFORT" value="300" />
    <xacro:property name="JOINT4_LOWER" value="-${M_PI/2}" />
    <xacro:property name="JOINT4_UPPER" value="${M_PI/2}" />
    <xacro:property name="JOINT4_VEL" value="1.0" />

    <!-- Joint 5 properties -->
    <xacro:property name="JOINT5_COOR" value="0.1255 0 0" />
    <xacro:property name="JOINT5_EFFORT" value="300" />
    <xacro:property name="JOINT5_LOWER" value="-${M_PI/2}" />
    <xacro:property name="JOINT5_UPPER" value="${M_PI/2}" />
    <xacro:property name="JOINT5_VEL" value="1.0" />

 <!-- ///////////// WORLD LINK FOR GAZEBO ///////////// -->
    <link name="world"/>

    <joint name="fixed" type="fixed">
        <parent link="world"/>
        <child link="base_link"/>
    </joint>

<!-- ////////////////  BASE LINK  ///////////////////// -->
    <link name="base_link">
        <visual>
            <origin xyz="${JOINT1_COOR}" rpy="${M_PI} 0 0" />
            <geometry>
                <mesh filename="package://um_description/meshes/base.STL" scale="1 1 1" />
            </geometry>
            <material name="Grey" />
        </visual>
        <collision>
            <origin xyz="${JOINT1_COOR}" rpy="${M_PI} 0 0" />
            <geometry>
                <mesh filename="package://um_description/meshes/base.STL" scale="1 1 1" />
            </geometry>        
        </collision>
        <xacro:inertia_matrix mass="1" />
    </link>

    <joint name="joint1" type="prismatic">
        <parent link="base_link"/>
        <child link="link1"/>
        <origin xyz="${JOINT1_COOR}" rpy="${M_PI} 0 0" />
        <axis xyz="1 0 0"/>
        <limit effort="${JOINT1_EFFORT}" lower="${JOINT1_LOWER}" upper="${JOINT1_UPPER}" velocity="${JOINT1_VEL}" />
        <dynamics damping="${DAMPING}" friction="${FRICTION}" />
    </joint>

    <!-- /////////////////  LINK 1  //////////////////////// -->
    <link name="link1">
        <visual>
            <origin xyz="${JOINT2_COOR}" rpy="0 0 0"/>
            <geometry>
                <mesh filename="package://um_description/meshes/link1.STL" scale="1 1 1"/>
            </geometry>
            <material name="Orange" />
        </visual>
        <collision>
            <origin xyz="${JOINT2_COOR}" rpy="0 0 0"/>
            <geometry>
                <mesh filename="package://um_description/meshes/link1.STL" scale="1 1 1"/>
            </geometry>   
        </collision>
        <xacro:inertia_matrix mass="1" />        
    </link>

    <joint name="joint2" type="revolute">
        <parent link="link1" />
        <child link="link2" />
        <origin xyz="${JOINT2_COOR}" rpy="0 0 0" />
        <axis xyz="0 0 1" />
        <limit effort="${JOINT2_EFFORT}" lower="${JOINT2_LOWER}" upper="${JOINT2_UPPER}" velocity="${JOINT2_VEL}" />
        <dynamics damping="${DAMPING}" friction="${FRICTION}" />
    </joint>

    <!-- /////////////////  LINK 2  //////////////////////// -->
    <link name="link2">
        <visual>
            <origin xyz="0 0 0" rpy="0 0 0" />
            <geometry>
                <mesh filename="package://um_description/meshes/link2.STL" scale="1 1 1" />
            </geometry>
            <material name="Grey" />
        </visual>
        <collision>
            <origin xyz="0 0 0" rpy="0 0 0" />
            <geometry>
                <mesh filename="package://um_description/meshes/link2.STL" scale="1 1 1" />            
            </geometry>
        </collision>
        <xacro:inertia_matrix mass="1" />
    </link>

    <joint name="joint3" type="revolute">
        <parent link="link2" />
        <child link="link3" />
        <origin xyz="${JOINT3_COOR}" rpy="0 0 0" />
        <axis xyz="1 0 0" />
        <limit effort="${JOINT3_EFFORT}" lower="${JOINT3_LOWER}" upper="${JOINT3_UPPER}" velocity="${JOINT3_VEL}" />
        <dynamics damping="${DAMPING}" friction="${FRICTION}" />
    </joint>

    <!-- /////////////////  LINK 3  //////////////////////// -->
    <link name="link3">
        <visual>
            <origin xyz="0 0 0" rpy="0 0 0" />
            <geometry>
                <mesh filename="package://um_description/meshes/link3.STL" scale="1 1 1" />
            </geometry>
            <material name="Orange" />
        </visual>
        <collision>
            <origin xyz="0 0 0" rpy="0 0 0" />
            <geometry>
                <mesh filename="package://um_description/meshes/link3.STL" scale="1 1 1" />            
            </geometry>
        </collision>
        <xacro:inertia_matrix mass="1" />
    </link>

    <joint name="joint4" type="revolute">
        <parent link="link3" />
        <child link="link4" />
        <origin xyz="${JOINT4_COOR}" rpy="0 0 0" />
        <axis xyz="0 1 0" />
        <limit effort="${JOINT4_EFFORT}" lower="${JOINT4_LOWER}" upper="${JOINT4_UPPER}" velocity="${JOINT4_VEL}" />
        <dynamics damping="${DAMPING}" friction="${FRICTION}" />
    </joint>

    <!-- /////////////////  LINK 4  //////////////////////// -->
    <link name="link4">
        <visual>
            <origin xyz="0 0 0" rpy="0 0 0" />
            <geometry>
                <mesh filename="package://um_description/meshes/link4.STL" scale="1 1 1" />
            </geometry>
            <material name="Grey" />
        </visual>
        <collision>
            <origin xyz="0 0 0" rpy="0 0 0" />
            <geometry>
                <mesh filename="package://um_description/meshes/link4.STL" scale="1 1 1" />
            </geometry>        
        </collision>
        <xacro:inertia_matrix mass="1" />
    </link>

    <joint name="joint5" type="revolute">
        <parent link="link4" />
        <child link="link5" />
        <origin xyz="${JOINT5_COOR}" rpy="0 0 0" />
        <axis xyz="0 1 0" />
        <limit effort="${JOINT5_EFFORT}" lower="${JOINT5_LOWER}" upper="${JOINT5_UPPER}" velocity="${JOINT5_VEL}" />
        <dynamics damping="${DAMPING}" friction="${FRICTION}" />
    </joint>

    <!-- /////////////////  LINK 5  //////////////////////// -->
    <link name="link5">
        <visual>
            <origin xyz="0 0 0" rpy="0 0 0" />
            <geometry>
                <mesh filename="package://um_description/meshes/link5.STL" scale="1 1 1" />
            </geometry>
            <material name="Orange" />
        </visual>
        <collision>
            <origin xyz="0 0 0" rpy="0 0 0" />
            <geometry>
                <mesh filename="package://um_description/meshes/link5.STL" scale="1 1 1" />
            </geometry>       
        </collision>
        <xacro:inertia_matrix mass="1" />
    </link>

    <!-- /////////////////  GAZEBO  //////////////////////// -->

    <!-- Materials of all links in Gazebo -->
    <gazebo reference="base_link">
        <material>Gazebo/Grey</material>
    </gazebo>

    <gazebo reference="link1">
        <material>Gazebo/Orange</material>
    </gazebo>

    <gazebo reference="link2">
        <material>Gazebo/Grey</material>
    </gazebo>

    <gazebo reference="link3">
        <material>Gazebo/Orange</material>
    </gazebo>

    <gazebo reference="link4">
        <material>Gazebo/Grey</material>
    </gazebo>

    <gazebo reference="link5">
        <material>Gazebo/Orange</material>
    </gazebo>

    <!-- Transmissions for ROS Control -->
    <xacro:macro name="transmission_block" params="joint_name">
        <transmission name="tran1">
            <type>transmission_interface/SimpleTransmission</type>
            <joint name="${joint_name}">
                <hardwareInterface>hardware_interface/PositionJointInterface</hardwareInterface>
            </joint>
            <actuator name="motor1">
                <hardwareInterface>hardware_interface/PositionJointInterface</hardwareInterface>
                <mechanicalReduction>1</mechanicalReduction>
            </actuator>
        </transmission>
    </xacro:macro>

    <xacro:transmission_block joint_name="joint1" />
    <xacro:transmission_block joint_name="joint2" />
    <xacro:transmission_block joint_name="joint3" />
    <xacro:transmission_block joint_name="joint4" />
    <xacro:transmission_block joint_name="joint5" />

    <!-- ros_control plugin -->
    <gazebo>
        <plugin name="gazebo_ros_control" filename="libgazebo_ros_control.so">
            <robotNamespace>/um</robotNamespace>
            <robotSimType>gazebo_ros_control/DefaultRobotHWSim</robotSimType>
            <legacyModeNS>true</legacyModeNS>
        </plugin>
    </gazebo>

</robot>