<?xml version="1.0" ?>
<!-- =================================================================================== -->
<!-- |    This document was autogenerated by xacro from um.urdf.xacro                  | -->
<!-- |    EDITING THIS FILE BY HAND IS NOT RECOMMENDED                                 | -->
<!-- =================================================================================== -->
<robot name="um" xmlns:xacro="http://ros.org/wiki/xacro">
  <!-- Define the colors used in the um -->
  <material name="Grey">
    <color rgba="0.75 0.75 0.75 1"/>
  </material>
  <material name="Orange">
    <color rgba="1 0.4 0 1"/>
  </material>
  <material name="Black">
    <color rgba="0 0 0 1"/>
  </material>
  <material name="White">
    <color rgba="1 1 1 1"/>
  </material>
  <material name="Blue">
    <color rgba="0 0 1 1"/>
  </material>
  <material name="Red">
    <color rgba="1 0 0 1"/>
  </material>
  <material name="Green">
    <color rgba="0 1 0 1"/>
  </material>
  <!-- ////////////////  BOTTOM JOINT  ///////////////////// -->
  <joint name="bottom_joint" type="fixed">
    <parent link="base_link"/>
    <child link="bottom_link"/>
    <origin rpy="0 0 0" xyz="0 0 0"/>
  </joint>
  <link name="bottom_link">
    <visual>
      <origin rpy="0 0 0" xyz="0 0 -0.05"/>
      <geometry>
        <box size="1 1 0.02"/>
      </geometry>
      <material name="Green"/>
    </visual>
    <collision>
      <origin rpy="0 0 0" xyz="0 0 -0.05"/>
      <geometry>
        <box size="1 1 0.02"/>
      </geometry>
    </collision>
    <inertial>
      <mass value="500"/>
      <interia ixx="1.0" ixy="0" ixz="0" iyy="0.5" iyz="0" izz="1.0"/>
    </inertial>
  </link>
  <!-- ////////////////  BASE LINK  ///////////////////// -->
  <link name="base_link">
    <visual>
      <origin rpy="0 0 0" xyz="0 0 0"/>
      <geometry>
        <mesh filename="package://um_description/meshes/base.STL" scale="1 1 1"/>
      </geometry>
      <material name="Grey"/>
    </visual>
    <collision>
      <origin rpy="0 0 0" xyz="0 0 0"/>
      <geometry>
        <mesh filename="package://um_description/meshes/base.STL" scale="1 1 1"/>
      </geometry>
    </collision>
    <inertial>
      <mass value="1"/>
      <interia ixx="1.0" ixy="0" ixz="0" iyy="0.5" iyz="0" izz="1.0"/>
    </inertial>
  </link>
  <joint name="joint1" type="prismatic">
    <parent link="base_link"/>
    <child link="link1"/>
    <origin rpy="0 0 0" xyz="0 0 0"/>
    <axis xyz="1 0 0"/>
    <limit effort="300" lower="0" upper="0.59" velocity="1.0"/>
    <dynamics damping="50" friction="1"/>
  </joint>
  <!-- /////////////////  LINK 1  //////////////////////// -->
  <link name="link1">
    <visual>
      <origin rpy="0 0 0" xyz="0.055 -0.0075 0.1764"/>
      <geometry>
        <mesh filename="package://um_description/meshes/link1.STL" scale="1 1 1"/>
      </geometry>
      <material name="Orange"/>
    </visual>
    <collision>
      <origin rpy="0 0 0" xyz="0.055 -0.0075 0.1764"/>
      <geometry>
        <mesh filename="package://um_description/meshes/link1.STL" scale="1 1 1"/>
      </geometry>
    </collision>
    <inertial>
      <mass value="1"/>
      <interia ixx="1.0" ixy="0" ixz="0" iyy="0.5" iyz="0" izz="1.0"/>
    </inertial>
  </link>
  <joint name="joint2" type="revolute">
    <parent link="link1"/>
    <child link="link2"/>
    <origin rpy="0 0 0" xyz="0.055 -0.0075 0.1764"/>
    <axis xyz="0 0 1"/>
    <limit effort="300" lower="-3.1415926" upper="3.1415926" velocity="1.0"/>
    <dynamics damping="50" friction="1"/>
  </joint>
  <!-- /////////////////  LINK 2  //////////////////////// -->
  <link name="link2">
    <visual>
      <origin rpy="0 0 0" xyz="0 0 0"/>
      <geometry>
        <mesh filename="package://um_description/meshes/link2.STL" scale="1 1 1"/>
      </geometry>
      <material name="Grey"/>
    </visual>
    <collision>
      <origin rpy="0 0 0" xyz="0 0 0"/>
      <geometry>
        <mesh filename="package://um_description/meshes/link2.STL" scale="1 1 1"/>
      </geometry>
    </collision>
    <inertial>
      <mass value="1"/>
      <interia ixx="1.0" ixy="0" ixz="0" iyy="0.5" iyz="0" izz="1.0"/>
    </inertial>
  </link>
  <joint name="joint3" type="revolute">
    <parent link="link2"/>
    <child link="link3"/>
    <origin rpy="0 0 0" xyz="0.0349 0 0.0225"/>
    <axis xyz="1 0 0"/>
    <limit effort="300" lower="-3.1415926" upper="3.1415926" velocity="1.0"/>
    <dynamics damping="50" friction="1"/>
  </joint>
  <!-- /////////////////  LINK 3  //////////////////////// -->
  <link name="link3">
    <visual>
      <origin rpy="0 0 0" xyz="0 0 0"/>
      <geometry>
        <mesh filename="package://um_description/meshes/link3.STL" scale="1 1 1"/>
      </geometry>
      <material name="Orange"/>
    </visual>
    <collision>
      <origin rpy="0 0 0" xyz="0 0 0"/>
      <geometry>
        <mesh filename="package://um_description/meshes/link3.STL" scale="1 1 1"/>
      </geometry>
    </collision>
    <inertial>
      <mass value="1"/>
      <interia ixx="1.0" ixy="0" ixz="0" iyy="0.5" iyz="0" izz="1.0"/>
    </inertial>
  </link>
  <joint name="joint4" type="revolute">
    <parent link="link3"/>
    <child link="link4"/>
    <origin rpy="0 0 0" xyz="0.2655 0 -0.00025"/>
    <axis xyz="0 1 0"/>
    <limit effort="300" lower="-1.5707963" upper="1.5707963" velocity="1.0"/>
    <dynamics damping="50" friction="1"/>
  </joint>
  <!-- /////////////////  LINK 4  //////////////////////// -->
  <link name="link4">
    <visual>
      <origin rpy="0 0 0" xyz="0 0 0"/>
      <geometry>
        <mesh filename="package://um_description/meshes/link4.STL" scale="1 1 1"/>
      </geometry>
      <material name="Grey"/>
    </visual>
    <collision>
      <origin rpy="0 0 0" xyz="0 0 0"/>
      <geometry>
        <mesh filename="package://um_description/meshes/link4.STL" scale="1 1 1"/>
      </geometry>
    </collision>
    <inertial>
      <mass value="1"/>
      <interia ixx="1.0" ixy="0" ixz="0" iyy="0.5" iyz="0" izz="1.0"/>
    </inertial>
  </link>
  <joint name="joint5" type="revolute">
    <parent link="link4"/>
    <child link="link5"/>
    <origin rpy="0 0 0" xyz="0.1255 0 0"/>
    <axis xyz="0 1 0"/>
    <limit effort="300" lower="-1.5707963" upper="1.5707963" velocity="1.0"/>
    <dynamics damping="50" friction="1"/>
  </joint>
  <!-- /////////////////  LINK 5  //////////////////////// -->
  <link name="link5">
    <visual>
      <origin rpy="0 0 0" xyz="0 0 0"/>
      <geometry>
        <mesh filename="package://um_description/meshes/link5.STL" scale="1 1 1"/>
      </geometry>
      <material name="Orange"/>
    </visual>
    <collision>
      <origin rpy="0 0 0" xyz="0 0 0"/>
      <geometry>
        <mesh filename="package://um_description/meshes/link5.STL" scale="1 1 1"/>
      </geometry>
    </collision>
    <inertial>
      <mass value="1"/>
      <interia ixx="1.0" ixy="0" ixz="0" iyy="0.5" iyz="0" izz="1.0"/>
    </inertial>
  </link>
  <!-- /////////////////  GAZEBO  //////////////////////// -->
  <!-- Materials of all links in Gazebo -->
  <gazebo reference="base_link">
    <material>Gazebo/Grey</material>
  </gazebo>
  <gazebo reference="link1">
    <material>Gazebo/Orange</material>
  </gazebo>
  <gazebo reference="link2">
    <material>Gazebo/Grey</material>
  </gazebo>
  <gazebo reference="link3">
    <material>Gazebo/Orange</material>
  </gazebo>
  <gazebo reference="link4">
    <material>Gazebo/Grey</material>
  </gazebo>
  <gazebo reference="link5">
    <material>Gazebo/Orange</material>
  </gazebo>
  <transmission name="tran1">
    <type>transmission_interface/SimpleTransmission</type>
    <joint name="joint1">
      <hardwareInterface>hardware_interface/PositionJointInterface</hardwareInterface>
    </joint>
    <actuator name="motor1">
      <hardwareInterface>hardware_interface/PositionJointInterface</hardwareInterface>
      <mechanicalReduction>1</mechanicalReduction>
    </actuator>
  </transmission>
  <transmission name="tran1">
    <type>transmission_interface/SimpleTransmission</type>
    <joint name="joint2">
      <hardwareInterface>hardware_interface/PositionJointInterface</hardwareInterface>
    </joint>
    <actuator name="motor1">
      <hardwareInterface>hardware_interface/PositionJointInterface</hardwareInterface>
      <mechanicalReduction>1</mechanicalReduction>
    </actuator>
  </transmission>
  <transmission name="tran1">
    <type>transmission_interface/SimpleTransmission</type>
    <joint name="joint3">
      <hardwareInterface>hardware_interface/PositionJointInterface</hardwareInterface>
    </joint>
    <actuator name="motor1">
      <hardwareInterface>hardware_interface/PositionJointInterface</hardwareInterface>
      <mechanicalReduction>1</mechanicalReduction>
    </actuator>
  </transmission>
  <transmission name="tran1">
    <type>transmission_interface/SimpleTransmission</type>
    <joint name="joint4">
      <hardwareInterface>hardware_interface/PositionJointInterface</hardwareInterface>
    </joint>
    <actuator name="motor1">
      <hardwareInterface>hardware_interface/PositionJointInterface</hardwareInterface>
      <mechanicalReduction>1</mechanicalReduction>
    </actuator>
  </transmission>
  <transmission name="tran1">
    <type>transmission_interface/SimpleTransmission</type>
    <joint name="joint5">
      <hardwareInterface>hardware_interface/PositionJointInterface</hardwareInterface>
    </joint>
    <actuator name="motor1">
      <hardwareInterface>hardware_interface/PositionJointInterface</hardwareInterface>
      <mechanicalReduction>1</mechanicalReduction>
    </actuator>
  </transmission>
  <!-- ros_control plugin -->
  <gazebo>
    <plugin filename="libgazebo_ros_control.so" name="gazebo_ros_control">
      <robotNamespace>/um</robotNamespace>
    </plugin>
  </gazebo>
</robot>

